Workbook

Sheet 补货建议-每月快照
A1: 时间 | B1: MSKU | C1: 品名 | D1: 店铺-老 | E1: 新品/老品 | F1: 开售时间 | G1: 日均 | H1: 7天日均 | I1: 14天日均 | J1: 28天日均 | K1: 应用规则 | L1: 7天销量总和 | M1: 7天内是否有0销量 | N1: 7天日期范围 | O1: 14天日期范围 | P1: 28天日期范围 | Q1: FBA库存 | R1: FBA在途 | S1: 海外仓可用 | T1: 海外仓在途 | U1: 本地可用 | V1: 待检待上架量 | W1: 待交付 | X1: 采购成本 | Y1: 头程费用 | Z1: 店铺
A2: 46235 | B2: JY01102 | C2: New1-【JY01102】-ET-鲜花女孩婴儿沐浴蜂窝-进益 | D2: 进益-US | E2: 老品 | F2: 44951 | G2: 3.06 | H2: 3.43 | I2: 3.21 | J2: 2.79 | K2: 规则④-老品(加权) | L2: 24 | M2: 否 | N2: 2026-07-24~2026-07-30 | O2: 2026-07-17~2026-07-30 | P2: 2026-07-03~2026-07-30 | Q2: 387 | R2: 0 | S2: 1320 | T2: 0 | U2: 660 | V2: 0 | W2: 0 | X2: 13.5 | Y2: 0.61290286 | Z2: =_xlfn.XLOOKUP(B2,店铺分配!A:A,店铺分配!C:C) -> 进益-US
A3: 46266 | B3: JY01102 | C3: New1-【JY01102】-ET-鲜花女孩婴儿沐浴蜂窝-进益 | D3: 进益-US | E3: 老品 | F3: 44951 | G3: 1.29 | H3: 1.29 | I3: 1.29 | J3: 1.61 | K3: 规则④-老品(7天) | L3: 9 | M3: 是 | N3: 2026-08-24~2026-08-30 | O3: 2026-08-17~2026-08-30 | P3: 2026-08-03~2026-08-30 | Q3: 341 | R3: 0 | S3: 1320 | T3: 0 | U3: 660 | V3: 0 | W3: 0 | X3: 13.5 | Y3: 0.61290286 | Z3: =_xlfn.XLOOKUP(B3,店铺分配!A:A,店铺分配!C:C) -> 进益-US
A4: 46296 | B4: JY01102 | C4: New1-【JY01102】-ET-鲜花女孩婴儿沐浴蜂窝-进益 | D4: 进益-US | E4: 老品 | F4: 44951 | G4: 1 | H4: 1 | I4: 0.93 | J4: 1.18 | K4: 规则④-老品(7天) | L4: 7 | M4: 是 | N4: 2026-09-23~2026-09-29 | O4: 2026-09-16~2026-09-29 | P4: 2026-09-02~2026-09-29 | Q4: 304 | R4: 0 | S4: 1320 | T4: 0 | U4: 660 | V4: 0 | W4: 0 | X4: 13.5 | Y4: 0.61290286 | Z4: =_xlfn.XLOOKUP(B4,店铺分配!A:A,店铺分配!C:C) -> 进益-US
A5: 46235 | B5: JY01105 | C5: New1-【JY01105】-粉色1岁生日蜂窝八件套-进益（淘汰） | D5: 进益-US | E5: 老品 | F5: 44935 | G5: 0.09 | H5: 0.14 | I5: 0.07 | J5: 0.07 | K5: 规则④-老品(加权) | L5: 1 | M5: 是 | N5: 2026-07-24~2026-07-30 | O5: 2026-07-17~2026-07-30 | P5: 2026-07-03~2026-07-30 | Q5: 7 | R5: 0 | S5: 70 | T5: 0 | U5: 1 | V5: 0 | W5: 0 | X5: 8.8 | Y5: 0.55685714 | Z5: =_xlfn.XLOOKUP(B5,店铺分配!A:A,店铺分配!C:C) -> 进益-US
A6: 46266 | B6: JY01105 | C6: New1-【JY01105】-粉色1岁生日蜂窝八件套-进益（淘汰） | D6: 进益-US | E6: 老品 | F6: 44935 | G6: 0.12 | H6: 0.14 | I6: 0.14 | J6: 0.11 | K6: 规则④-老品(加权) | L6: 1 | M6: 是 | N6: 2026-08-24~2026-08-30 | O6: 2026-08-17~2026-08-30 | P6: 2026-08-03~2026-08-30 | Q6: 4 | R6: 70 | S6: 0 | T6: 0 | U6: 1 | V6: 0 | W6: 0 | X6: 8.8 | Y6: 0.55685714 | Z6: =_xlfn.XLOOKUP(B6,店铺分配!A:A,店铺分配!C:C) -> 进益-US
A7: 46296 | B7: JY01105 | C7: New1-【JY01105】-粉色1岁生日蜂窝八件套-进益（淘汰） | D7: 进益-US | E7: 老品 | F7: 44935 | G7: 0.09 | H7: 0.14 | I7: 0.07 | J7: 0.07 | K7: 规则④-老品(加权) | L7: 1 | M7: 是 | N7: 2026-09-23~2026-09-29 | O7: 2026-09-16~2026-09-29 | P7: 2026-09-02~2026-09-29 | Q7: 71 | R7: 6 | S7: 0 | T7: 0 | U7: 1 | V7: 0 | W7: 0 | X7: 8.8 | Y7: 0.55685714 | Z7: =_xlfn.XLOOKUP(B7,店铺分配!A:A,店铺分配!C:C) -> 进益-US
A8: 46235 | B8: JY01109 | C8: New1-【JY01109】-黑白30岁墓碑门联-进益（停售） | D8: 进益-US | E8: 老品 | F8: 44935 | G8: 0.58 | H8: 0.71 | I8: 0.57 | J8: 0.5 | K8: 规则④-老品(加权) | L8: 5 | M8: 是 | N8: 2026-07-24~2026-07-30 | O8: 2026-07-17~2026-07-30 | P8: 2026-07-03~2026-07-30 | Q8: 21 | R8: 0 | S8: 0 | T8: 0 | U8: 4 | V8: 0 | W8: 0 | X8: 9 | Y8: 0.67058824 | Z8: =_xlfn.XLOOKUP(B8,店铺分配!A:A,店铺分配!C:C) -> 进益-US
A9: 46266 | B9: JY01109 | C9: New1-【JY01109】-黑白30岁墓碑门联-进益（停售） | D9: 进益-US | E9: 老品 | F9: 44935 | G9: 0.65 | H9: 0.71 | I9: 0.5 | J9: 0.68 | K9: 规则④-老品(加权) | L9: 5 | M9: 是 | N9: 2026-08-24~2026-08-30 | O9: 2026-08-17~2026-08-30 | P9: 2026-08-03~2026-08-30 | Q9: 1 | R9: 0 | S9: 0 | T9: 0 | U9: 4 | V9: 0 | W9: 0 | X9: 9 | Y9: 0.67058824 | Z9: =_xlfn.XLOOKUP(B9,店铺分配!A:A,店铺分配!C:C) -> 进益-US
A10: 46296 | B10: JY01109 | C10: New1-【JY01109】-黑白30岁墓碑门联-进益（停售） | D10: 进益-US | E10: 老品 | F10: 44935 | G10: 0.07 | H10: 0 | I10: 0.07 | J10: 0.04 | K10: 规则④-老品(7天) | L10: 0 | M10: 是 | N10: 2026-09-23~2026-09-29 | O10: 2026-09-16~2026-09-29 | P10: 2026-09-02~2026-09-29 | Q10: 1 | R10: 0 | S10: 0 | T10: 0 | U10: 4 | V10: 0 | W10: 0 | X10: 9 | Y10: 0.67058824 | Z10: =_xlfn.XLOOKUP(B10,店铺分配!A:A,店铺分配!C:C) -> 进益-US
A11: 46235 | B11: JY01110 | C11: New1-【JY01110】-黑玫金气球40岁生日门联-进益（淘汰） | D11: 进益-US | E11: 老品 | F11: 44950 | G11: 0.66 | H11: 0.71 | I11: 0.79 | J11: 0.57 | K11: 规则④-老品(加权) | L11: 5 | M11: 是 | N11: 2026-07-24~2026-07-30 | O11: 2026-07-17~2026-07-30 | P11: 2026-07-03~2026-07-30 | Q11: 85 | R11: 0 | S11: 0 | T11: 0 | U11: 88 | V11: 0 | W11: 0 | X11: 9 | Y11: 0.79113043 | Z11: =_xlfn.XLOOKUP(B11,店铺分配!A:A,店铺分配!C:C) -> 进益-US
A12: 46266 | B12: JY01110 | C12: New1-【JY01110】-黑玫金气球40岁生日门联-进益（淘汰） | D12: 进益-US | E12: 老品 | F12: 44950 | G12: 0.78 | H12: 1 | I12: 0.71 | J12: 0.68 | K12: 规则④-老品(加权) | L12: 7 | M12: 是 | N12: 2026-08-24~2026-08-30 | O12: 2026-08-17~2026-08-30 | P12: 2026-08-03~2026-08-30 | Q12: 66 | R12: 0 | S12: 0 | T12: 0 | U12: 88 | V12: 0 | W12: 0 | X12: 9 | Y12: 0.79113043 | Z12: =_xlfn.XLOOKUP(B12,店铺分配!A:A,店铺分配!C:C) -> 进益-US
A13: 46296 | B13: JY01110 | C13: New1-【JY01110】-黑玫金气球40岁生日门联-进益（淘汰） | D13: 进益-US | E13: 老品 | F13: 44950 | G13: 0.71 | H13: 0.71 | I13: 0.64 | J13: 0.75 | K13: 规则④-老品(7天) | L13: 5 | M13: 是 | N13: 2026-09-23~2026-09-29 | O13: 2026-09-16~2026-09-29 | P13: 2026-09-02~2026-09-29 | Q13: 43 | R13: 0 | S13: 0 | T13: 0 | U13: 88 | V13: 0 | W13: 0 | X13: 9 | Y13: 0.79113043 | Z13: =_xlfn.XLOOKUP(B13,店铺分配!A:A,店铺分配!C:C) -> 进益-US
... A5854: 46296 | B5854: SX00475 | C5854: 2609-【SX00475】-ET-彩色DIY岁数毛毡套装-势兴 | D5854: 势兴-US | E5854: 开售在半个月内 | F5854: 46292 | G5854: 2 | H5854: 0.29 | I5854: 0.14 | J5854: 0.07 | K5854: 规则⑤-开售在半个月内(近3天最大) | L5854: 2 | M5854: 是 | N5854: 2026-09-23~2026-09-29 | O5854: 2026-09-16~2026-09-29 | P5854: 2026-09-02~2026-09-29 | Q5854: 128 | R5854: 30 | S5854: 0 | T5854: 0 | U5854: 39 | V5854: 0 | W5854: 1 | X5854: 6.5 | Y5854: 1.9555 | Z5854: =_xlfn.XLOOKUP(B5854,店铺分配!A:A,店铺分配!C:C) -> 势兴-US

Sheet 商品信息
A1: 店铺 | B1: MSKU | C1: 品名 | D1: 新品/老品 | E1: 是否年份 | F1: 主题 | G1: 类别 | H1: 开售时间 | I1: 岁数 | J1: 岁数（新）
A2: 进益-US | B2: JY01102 | C2: New1-【JY01102】-ET-鲜花女孩婴儿沐浴蜂窝-进益 | D2: 老品 | E2: 否 | F2: 婴儿沐浴 | G2: 蜂窝 | H2: 44951 | I2: 婴幼儿（无明确岁数） | J2: 婴幼儿（无明确岁数）
A3: 进益-US | B3: JY01105 | C3: New1-【JY01105】-粉色1岁生日蜂窝八件套-进益（淘汰） | D3: 老品 | E3: 否 | F3: 生日 | G3: 蜂窝 | H3: 44935 | I3: 1岁 | J3: 1岁
A4: 进益-US | B4: JY01109 | C4: New1-【JY01109】-黑白30岁墓碑门联-进益（停售） | D4: 老品 | E4: 否 | F4: 生日 | G4: 门联 | H4: 44935 | I4: 1岁 | J4: 1岁
A5: 进益-US | B5: JY01110 | C5: New1-【JY01110】-黑玫金气球40岁生日门联-进益（淘汰） | D5: 老品 | E5: 否 | F5: 生日 | G5: 门联 | H5: 44950 | I5: 30岁 | J5: 30岁
A6: 进益-US | B6: JY01111 | C6: New1-【JY01111】-黑玫金气球无岁数生日门联-进益 | D6: 老品 | E6: 否 | F6: 生日 | G6: 门联 | H6: 44949 | I6: 40岁 | J6: 40岁
A7: 进益-US | B7: JY01113 | C7: New3-【JY01113】-黑玫金气球50岁生日门联-进益（淘汰） | D7: 老品 | E7: 否 | F7: 生日 | G7: 门联 | H7: 44989 | I7: 无岁数 | J7: 无岁数
A8: 进益-US | B8: JY01125 | C8: New5-【JY01125】-甜甜圈甜蜜1岁生日蜂窝-进益（停售） | D8: 老品 | E8: 否 | F8: 生日 | G8: 蜂窝 | H8: 45074 | I8: 50岁 | J8: 50岁
A9: 进益-US | B9: JY01126 | C9: New6-【JY01126】-鲜花无岁数生日蜂窝-进益 | D9: 老品 | E9: 否 | F9: 生日 | G9: 蜂窝 | H9: 45082 | I9: 1岁 | J9: 1岁
A10: 进益-US | B10: JY01130 | C10: New7-【JY01130】-ET-甜甜圈甜蜜2岁生日蜂窝-进益（淘汰） | D10: 老品 | E10: 否 | F10: 生日 | G10: 蜂窝 | H10: 45117 | I10: 无岁数 | J10: 无岁数
A11: 进益-US | B11: JY01132 | C11: New8-【JY01132】-鲜花无岁数生日漩涡-进益 | D11: 老品 | E11: 否 | F11: 生日 | G11: 漩涡 | H11: 45151 | I11: 2岁 | J11: 2岁
A12: 进益-US | B12: JY01136 | C12: New9-【JY01136】-金粉80岁眼镜24件套-进益（四分袋） | D12: 老品 | E12: 否 | F12: 生日 | G12: 眼镜 | H12: 45197 | I12: 无岁数 | J12: 无岁数
A13: 进益-US | B13: JY01138 | C13: New10-【JY01138】-粉金60岁盒子3件套-进益（淘汰） | D13: 老品 | E13: 否 | F13: 生日 | G13: 盒子 | H13: 45221 | I13: 80岁 | J13: 80岁
... A1623: 势兴-US | B1623: SX00461 | C1623: 2606-【SX00461】-金粉40岁小号长横幅-势兴 | D1623: 老品 | E1623: 否 | F1623: 生日 | G1623: 套装 | H1623: 46180 | I1623: 16岁 | J1623: 16岁
A1624: 拼途-US | B1624: PT53626 | C1624: 2026-【PT53626】-粉金13岁亚克力摆件4件套-拼途 | D1624: 老品 | E1624: 是 | F1624: 生日 | G1624: 套装 | H1624: 46180
A1625: 思业成-US | B1625: SYC677 | C1625: 【SYC677】-香槟金50岁流苏花球套装-思业成（整套真空+外面套opp袋子） | D1625: 老品 | E1625: 否 | F1625: 生日 | G1625: 套装 | H1625: 46180
A1626: 思业成-US | B1626: SYC682 | C1626: 2026-【SYC682】-金粉1981年份签名本-思业成 | D1626: 老品 | E1626: 是 | F1626: 生日 | G1626: 套装 | H1626: 46180
A1627: 大卖-US | B1627: DM21480 | C1627: 2026-【DM21480】-香槟金21岁年份双横幅套装-大卖（点胶固定） | D1627: 老品 | E1627: 是 | F1627: 生日 | G1627: 套装 | H1627: 46185
A1628: 辰瑞-US | B1628: CR32573 | C1628: 【CR32573】-香槟金50岁皇冠纸扇生日套装-辰瑞 | D1628: 老品 | E1628: 否 | F1628: 生日 | G1628: 套装 | H1628: 46182
A1629: 思业成-US | B1629: SYC681 | C1629: 2026-【SYC681】-金粉2001年份签名本-思业成 | D1629: 老品 | E1629: 是 | F1629: 生日 | G1629: 套装 | H1629: 46180
A1630: 势兴-US | B1630: SX00457 | C1630: 2606-【SX00457】-警告13岁签名本-势兴 | D1630: 老品 | E1630: 否 | F1630: 生日 | G1630: 套装 | H1630: 46182
A1631: 争艳-US | B1631: ZY02318 | C1631: 【ZY02318】-香槟金60岁花球纸扇生日套装-争艳（整体真空+外面套opp袋） | D1631: 老品 | E1631: 否 | F1631: 生日 | G1631: 套装 | H1631: 46185
A1632: 拼途-US | B1632: PT53629 | C1632: 2026-【PT53629】-蓝银13岁亚克力摆件4件套-拼途（淘汰） | D1632: 老品 | E1632: 是 | F1632: 生日 | G1632: 套装 | H1632: 46182
A1633: 进益-US | B1633: JY01326 | C1633: 2606-【JY01326】-ET-香槟金1岁照片灯饰横幅套装-进益（点胶固定+气球真空） | D1633: 老品 | E1633: 否 | F1633: 生日 | G1633: 套装 | H1633: 46180
A1634: 思业成-US | B1634: SYC676 | C1634: 【SYC676】-香槟金40岁流苏花球套装-思业成（整套真空+外面套opp袋子） | D1634: 老品 | E1634: 否 | F1634: 生日 | G1634: 套装 | H1634: 46184
A1635: 思业成-US | B1635: SYC678 | C1635: 2026-【SYC678】-黑金85岁眼镜24件套-思业成（四分袋） | D1635: 老品 | E1635: 是 | F1635: 生日 | G1635: 套装 | H1635: 46183
... A1952: 势兴-US | B1952: SX00475 | C1952: 2609-【SX00475】-ET-彩色DIY岁数毛毡套装-势兴 | D1952: 开售在半个月内 | E1952: 否 | F1952: 生日 | G1952: 套装 | H1952: 46292

Sheet 销量数据-每月
A1: MSKU | B1: 时间 | C1: 销量
A2: 10zhounian kl | B2: 45962 | C2: 37
A3: 10zhounian kl | B3: 45992 | C3: 25
A4: 10zhounian kl | B4: 46023 | C4: 23
A5: 10zhounian kl | B5: 46054 | C5: 7
A6: 10zhounian kl | B6: 46082 | C6: 1
A7: 10zhounian kl | B7: 46143 | C7: 1
A8: 1987Y11211 | B8: 45962 | C8: 20
A9: 1987Y11211 | B9: 45992 | C9: 8
A10: 1987Y11211 | B10: 46023 | C10: 19
A11: 1987Y11211 | B11: 46054 | C11: 17
A12: 1987Y11211 | B12: 46082 | C12: 28
A13: 1987Y11211 | B13: 46113 | C13: 34
... A10142: ZY02316 | B10142: 46143 | C10142: 38
A10143: (空白) | B10143: (空白)
A10144: 总计 | C10144: 834112

Sheet 采购数据-每月
A1: 店铺 | B1: SKU | C1: 采购量 | D1: 采购日期 | E1: 采购类型 | F1: MSKU | G1: 备注 | K1: SKU | L1: 采购量
A2: 创奇-US | B2: CQ11708 | C2: 200 | D2: 46022 | E2: 年前采购 | F2: CQ11708 | K2: CQ11919B | L2: 150
A3: 进益-US | B3: JY01195 | C3: 200 | D3: 46022 | E3: 年前采购 | F3: JY01195 | K3: CQ11932E | L3: 200
A4: 思业成-US | B4: SYC563 | C4: 300 | D4: 46022 | E4: 年前采购 | F4: SYC563 | K4: DX05962 | L4: 50
A5: 争艳-US | B5: ZY02267 | C5: 300 | D5: 46022 | E5: 年前采购 | F5: ZY02267 | K5: JY01167 | L5: 100
A6: 进益-US | B6: JY01287 | C6: 200 | D6: 46026 | E6: 年前采购 | F6: JY01287 | K6: JY01216 | L6: 100
A7: 创奇-US | B7: CQ11576 | C7: 300 | D7: 46026 | E7: 年前采购 | F7: CQ11576 | K7: CQ11577 | L7: 200
A8: 进益-US | B8: JY01177 | C8: 200 | D8: 46026 | E8: 年前采购 | F8: JY01177 | K8: CQ11634 | L8: 200
A9: 大卖-US | B9: DM21324 | C9: 30 | D9: 46026 | E9: 年前采购 | F9: DM21324 | K9: CQ11633 | L9: 200
A10: 思业成-US | B10: SYC567 | C10: 300 | D10: 46026 | E10: 年前采购 | F10: SYC567 | K10: CQ11827 | L10: 100
A11: 思业成-US | B11: SYC160 | C11: 30 | D11: 46026 | E11: 年前采购 | F11: SYC160 | K11: CQ11822 | L11: 150
A12: 思业成-US | B12: SYC478 | C12: 200 | D12: 46026 | E12: 年前采购 | F12: SYC478 | K12: CQ11843A | L12: 100
A13: 拼途-US | B13: PT53356 | C13: 40 | D13: 46026 | E13: 年前采购 | F13: PT53356 | K13: SX00143 | L13: 80
... A793: 定行-US | B793: DX05799 | C793: 300 | D793: 46038 | E793: 年前采购 | F793: DX05799 | K793: hj 60n jb hb | L793: 50
A794: 定行-US | B794: DX05798 | C794: 300 | D794: 46038 | E794: 年前采购 | F794: DX05798
A795: 定行-US | B795: DX05717 | C795: 30 | D795: 46038 | E795: 年前采购 | F795: DX05717
A796: 定行-US | B796: DX05707 | C796: 30 | D796: 46038 | E796: 年前采购 | F796: DX05707
A797: 定行-US | B797: DX05693 | C797: 50 | D797: 46038 | E797: 年前采购 | F797: DX05693
A798: 定行-US | B798: DX05584 | C798: 100 | D798: 46038 | E798: 年前采购 | F798: DX05584
A799: 定行-US | B799: DX05983 | C799: 200 | D799: 46038 | E799: 年前采购 | F799: DX05983
A800: 定行-US | B800: DX05982 | C800: 200 | D800: 46038 | E800: 年前采购 | F800: DX05982
A801: 定行-US | B801: DX05966 | C801: 100 | D801: 46038 | E801: 年前采购 | F801: DX05966
A802: 定行-US | B802: DX05948 | C802: 200 | D802: 46038 | E802: 年前采购 | F802: DX05948
A803: 定行-US | B803: DX05947 | C803: 200 | D803: 46038 | E803: 年前采购 | F803: DX05947
A804: 定行-US | B804: DX05945 | C804: 200 | D804: 46038 | E804: 年前采购 | F804: DX05945
A805: 定行-US | B805: DX05944 | C805: 200 | D805: 46038 | E805: 年前采购 | F805: DX05944
... A2339: 辰瑞-US | B2339: CR32574 | C2339: 300 | D2339: 46142.794 | E2339: 年后采购 | F2339: CR32574
A2340: 辰瑞-US | B2340: CR32488 | C2340: 250 | D2340: 45976 | E2340: 年货采购 | F2340: CR32488 | G2340: 非年份11月采购
A2341: 辰瑞-US | B2341: CR32486 | C2341: 380 | D2341: 45976 | E2341: 年货采购 | F2341: CR32486 | G2341: 非年份11月采购
A2342: 辰瑞-US | B2342: CR32487 | C2342: 340 | D2342: 45976 | E2342: 年货采购 | F2342: CR32487 | G2342: 非年份11月采购
A2343: 辰瑞-US | B2343: CR32484 | C2343: 780 | D2343: 45976 | E2343: 年货采购 | F2343: CR32484 | G2343: 非年份11月采购
A2344: 辰瑞-US | B2344: CR32483 | C2344: 370 | D2344: 45976 | E2344: 年货采购 | F2344: CR32483 | G2344: 非年份11月采购
A2345: 辰瑞-US | B2345: CR32482 | C2345: 240 | D2345: 45976 | E2345: 年货采购 | F2345: CR32482 | G2345: 非年份11月采购
A2346: 辰瑞-US | B2346: CR32481 | C2346: 200 | D2346: 45976 | E2346: 年货采购 | F2346: CR32481 | G2346: 非年份11月采购
A2347: 辰瑞-US | B2347: CR32474 | C2347: 280 | D2347: 45976 | E2347: 年货采购 | F2347: CR32474 | G2347: 非年份11月采购
A2348: 辰瑞-US | B2348: CR32472 | C2348: 200 | D2348: 45976 | E2348: 年货采购 | F2348: CR32472 | G2348: 非年份11月采购
A2349: 辰瑞-US | B2349: CR32468 | C2349: 430 | D2349: 45976 | E2349: 年货采购 | F2349: CR32468 | G2349: 非年份11月采购
A2350: 辰瑞-US | B2350: CR32467 | C2350: 540 | D2350: 45976 | E2350: 年货采购 | F2350: CR32467 | G2350: 非年份11月采购
A2351: 辰瑞-US | B2351: CR32466 | C2351: 200 | D2351: 45976 | E2351: 年货采购 | F2351: CR32466 | G2351: 非年份11月采购
... A5776: 创奇-US | B5776: CQ11817 | C5776: 50 | D5776: 46235 | E5776: 年后采购 | F5776: CQ11817 | G5776: 8.31 创奇 常规采购
...

Sheet 头程费用-明细
A1: 时间 | B1: MSKU | C1: 已发走库存 | D1: 最新一次发货时间 | E1: 最后一次发货的前三个月时间 | F1: 发货数量 | G1: 总费用 | H1: 单件头程费用
A2: 46235 | B2: JY01102 | C2: 1707 | D2: 46045 | E2: 45955 | F2: 875 | G2: 536.29 | H2: 0.61290286 | I2: =_xlfn.XLOOKUP(B2,'补货建议-每月快照'!B:B,'补货建议-每月快照'!E:E) -> 老品
A3: 46266 | B3: JY01102 | C3: 1661 | D3: 46045 | E3: 45955 | F3: 875 | G3: 536.29 | H3: 0.61290286 | I3: =_xlfn.XLOOKUP(B3,'补货建议-每月快照'!B:B,'补货建议-每月快照'!E:E) -> 老品
A4: 46296 | B4: JY01102 | C4: 1624 | D4: 46045 | E4: 45955 | F4: 875 | G4: 536.29 | H4: 0.61290286 | I4: =_xlfn.XLOOKUP(B4,'补货建议-每月快照'!B:B,'补货建议-每月快照'!E:E) -> 老品
A5: 46235 | B5: JY01105 | C5: 77 | D5: 46032 | E5: 45942 | F5: 35 | G5: 19.49 | H5: 0.55685714 | I5: =_xlfn.XLOOKUP(B5,'补货建议-每月快照'!B:B,'补货建议-每月快照'!E:E) -> 老品
A6: 46266 | B6: JY01105 | C6: 74 | D6: 46032 | E6: 45942 | F6: 35 | G6: 19.49 | H6: 0.55685714 | I6: =_xlfn.XLOOKUP(B6,'补货建议-每月快照'!B:B,'补货建议-每月快照'!E:E) -> 老品
A7: 46296 | B7: JY01105 | C7: 77 | D7: 46032 | E7: 45942 | F7: 35 | G7: 19.49 | H7: 0.55685714 | I7: =_xlfn.XLOOKUP(B7,'补货建议-每月快照'!B:B,'补货建议-每月快照'!E:E) -> 老品
A8: 46235 | B8: JY01109 | C8: 21 | D8: 46053 | E8: 45963 | F8: 85 | G8: 57 | H8: 0.67058824 | I8: =_xlfn.XLOOKUP(B8,'补货建议-每月快照'!B:B,'补货建议-每月快照'!E:E) -> 老品
A9: 46266 | B9: JY01109 | C9: 1 | D9: 46053 | E9: 45963 | F9: 85 | G9: 57 | H9: 0.67058824 | I9: =_xlfn.XLOOKUP(B9,'补货建议-每月快照'!B:B,'补货建议-每月快照'!E:E) -> 老品
A10: 46296 | B10: JY01109 | C10: 1 | D10: 46053 | E10: 45963 | F10: 85 | G10: 57 | H10: 0.67058824 | I10: =_xlfn.XLOOKUP(B10,'补货建议-每月快照'!B:B,'补货建议-每月快照'!E:E) -> 老品
A11: 46235 | B11: JY01110 | C11: 85 | D11: 46053 | E11: 45963 | F11: 115 | G11: 90.98 | H11: 0.79113043 | I11: =_xlfn.XLOOKUP(B11,'补货建议-每月快照'!B:B,'补货建议-每月快照'!E:E) -> 老品
A12: 46266 | B12: JY01110 | C12: 66 | D12: 46053 | E12: 45963 | F12: 115 | G12: 90.98 | H12: 0.79113043 | I12: =_xlfn.XLOOKUP(B12,'补货建议-每月快照'!B:B,'补货建议-每月快照'!E:E) -> 老品
A13: 46296 | B13: JY01110 | C13: 43 | D13: 46053 | E13: 45963 | F13: 115 | G13: 90.98 | H13: 0.79113043 | I13: =_xlfn.XLOOKUP(B13,'补货建议-每月快照'!B:B,'补货建议-每月快照'!E:E) -> 老品
... A145: 46296 | B145: rongqiu xnn tz | C145: 0 | D145: 46061 | E145: 45971 | F145: 35 | G145: 43.69 | H145: 0 | I145: =_xlfn.XLOOKUP(B145,'补货建议-每月快照'!B:B,'补货建议-每月快照'!E:E) -> 老品
A146: 46235 | B146: 50sui xuanwo | C146: 0 | D146: 无匹配结果 | E146: #VALUE! | F146: 0 | G146: 0 | H146: 0 | I146: =_xlfn.XLOOKUP(B146,'补货建议-每月快照'!B:B,'补货建议-每月快照'!E:E) -> 老品
A147: 46266 | B147: 50sui xuanwo | C147: 0 | D147: 无匹配结果 | E147: #VALUE! | F147: 0 | G147: 0 | H147: 0 | I147: =_xlfn.XLOOKUP(B147,'补货建议-每月快照'!B:B,'补货建议-每月快照'!E:E) -> 老品
A148: 46296 | B148: 50sui xuanwo | C148: 0 | D148: 无匹配结果 | E148: #VALUE! | F148: 0 | G148: 0 | H148: 0 | I148: =_xlfn.XLOOKUP(B148,'补货建议-每月快照'!B:B,'补货建议-每月快照'!E:E) -> 老品
A149: 46235 | B149: SX00110 | C149: 209 | D149: 46043 | E149: 45953 | F149: 130 | G149: 97.48 | H149: 0.74984615 | I149: =_xlfn.XLOOKUP(B149,'补货建议-每月快照'!B:B,'补货建议-每月快照'!E:E) -> 老品
A150: 46266 | B150: SX00110 | C150: 264 | D150: 46043 | E150: 45953 | F150: 130 | G150: 97.48 | H150: 0.74984615 | I150: =_xlfn.XLOOKUP(B150,'补货建议-每月快照'!B:B,'补货建议-每月快照'!E:E) -> 老品
A151: 46296 | B151: SX00110 | C151: 232 | D151: 46043 | E151: 45953 | F151: 130 | G151: 97.48 | H151: 0.74984615 | I151: =_xlfn.XLOOKUP(B151,'补货建议-每月快照'!B:B,'补货建议-每月快照'!E:E) -> 老品
A152: 46235 | B152: SX00111 | C152: 311 | D152: 46039 | E152: 45949 | F152: 450 | G152: 238.77 | H152: 0.5306 | I152: =_xlfn.XLOOKUP(B152,'补货建议-每月快照'!B:B,'补货建议-每月快照'!E:E) -> 老品
A153: 46266 | B153: SX00111 | C153: 326 | D153: 46039 | E153: 45949 | F153: 450 | G153: 238.77 | H153: 0.5306 | I153: =_xlfn.XLOOKUP(B153,'补货建议-每月快照'!B:B,'补货建议-每月快照'!E:E) -> 老品
A154: 46296 | B154: SX00111 | C154: 331 | D154: 46039 | E154: 45949 | F154: 450 | G154: 238.77 | H154: 0.5306 | I154: =_xlfn.XLOOKUP(B154,'补货建议-每月快照'!B:B,'补货建议-每月快照'!E:E) -> 老品
A155: 46235 | B155: SX00114 | C155: 610 | D155: 46063 | E155: 45973 | F155: 1230 | G155: 806.66 | H155: 0.65582114 | I155: =_xlfn.XLOOKUP(B155,'补货建议-每月快照'!B:B,'补货建议-每月快照'!E:E) -> 老品
A156: 46266 | B156: SX00114 | C156: 484 | D156: 46063 | E156: 45973 | F156: 1230 | G156: 806.66 | H156: 0.65582114 | I156: =_xlfn.XLOOKUP(B156,'补货建议-每月快照'!B:B,'补货建议-每月快照'!E:E) -> 老品
A157: 46296 | B157: SX00114 | C157: 775 | D157: 46063 | E157: 45973 | F157: 1230 | G157: 806.66 | H157: 0.65582114 | I157: =_xlfn.XLOOKUP(B157,'补货建议-每月快照'!B:B,'补货建议-每月快照'!E:E) -> 老品
A158: 46235 | B158: SX00115 | C158: 727 | D158: 46053 | E158: 45963 | F158: 880 | G158: 541.28 | H158: 0.61509091 | I158: =_xlfn.XLOOKUP(B158,'补货建议-每月快照'!B:B,'补货建议-每月快照'!E:E) -> 老品
A159: 46266 | B159: SX00115 | C159: 609 | D159: 46053 | E159: 45963 | F159: 880 | G159: 541.28 | H159: 0.61509091 | I159: =_xlfn.XLOOKUP(B159,'补货建议-每月快照'!B:B,'补货建议-每月快照'!E:E) -> 老品
A160: 46296 | B160: SX00115 | C160: 555 | D160: 46053 | E160: 45963 | F160: 880 | G160: 541.28 | H160: 0.61509091 | I160: =_xlfn.XLOOKUP(B160,'补货建议-每月快照'!B:B,'补货建议-每月快照'!E:E) -> 老品
... A631: 46296 | B631: DM21355 | C631: 0 | D631: 46053 | E631: 45963 | F631: 15 | G631: 55.54 | H631: 0 | I631: =_xlfn.XLOOKUP(B631,'补货建议-每月快照'!B:B,'补货建议-每月快照'!E:E) -> 老品
A632: 46235 | B632: DM21362 | C632: 0 | D632: 无匹配结果 | E632: #VALUE! | F632: 0 | G632: 0 | H632: 0 | I632: =_xlfn.XLOOKUP(B632,'补货建议-每月快照'!B:B,'补货建议-每月快照'!E:E) -> 老品
A633: 46266 | B633: DM21362 | C633: 0 | D633: 无匹配结果 | E633: #VALUE! | F633: 0 | G633: 0 | H633: 0 | I633: =_xlfn.XLOOKUP(B633,'补货建议-每月快照'!B:B,'补货建议-每月快照'!E:E) -> 老品
A634: 46296 | B634: DM21362 | C634: 0 | D634: 无匹配结果 | E634: #VALUE! | F634: 0 | G634: 0 | H634: 0 | I634: =_xlfn.XLOOKUP(B634,'补货建议-每月快照'!B:B,'补货建议-每月快照'!E:E) -> 老品
A635: 46235 | B635: DM21367 | C635: 455 | D635: 46108 | E635: 46018 | F635: 253 | G635: 142.76 | H635: 0.56426877 | I635: =_xlfn.XLOOKUP(B635,'补货建议-每月快照'!B:B,'补货建议-每月快照'!E:E) -> 老品
A636: 46266 | B636: DM21367 | C636: 422 | D636: 46108 | E636: 46018 | F636: 253 | G636: 142.76 | H636: 0.56426877 | I636: =_xlfn.XLOOKUP(B636,'补货建议-每月快照'!B:B,'补货建议-每月快照'!E:E) -> 老品
A637: 46296 | B637: DM21367 | C637: 401 | D637: 46108 | E637: 46018 | F637: 253 | G637: 142.76 | H637: 0.56426877 | I637: =_xlfn.XLOOKUP(B637,'补货建议-每月快照'!B:B,'补货建议-每月快照'!E:E) -> 老品
A638: 46235 | B638: DM21368 | C638: 154 | D638: 46032 | E638: 45942 | F638: 110 | G638: 112.45 | H638: 1.0222727 | I638: =_xlfn.XLOOKUP(B638,'补货建议-每月快照'!B:B,'补货建议-每月快照'!E:E) -> 老品
A639: 46266 | B639: DM21368 | C639: 134 | D639: 46032 | E639: 45942 | F639: 110 | G639: 112.45 | H639: 1.0222727 | I639: =_xlfn.XLOOKUP(B639,'补货建议-每月快照'!B:B,'补货建议-每月快照'!E:E) -> 老品
A640: 46296 | B640: DM21368 | C640: 116 | D640: 46032 | E640: 45942 | F640: 110 | G640: 112.45 | H640: 1.0222727 | I640: =_xlfn.XLOOKUP(B640,'补货建议-每月快照'!B:B,'补货建议-每月快照'!E:E) -> 老品
A641: 46235 | B641: DM21370 | C641: 94 | D641: 46046 | E641: 45956 | F641: 250 | G641: 390.36 | H641: 1.56144 | I641: =_xlfn.XLOOKUP(B641,'补货建议-每月快照'!B:B,'补货建议-每月快照'!E:E) -> 老品
...

Sheet 店铺分配
A1: MSKU | B1: 品名 | C1: 店铺 | E1: 创奇-US | F1: 创奇-US雨宜B | G1: 创奇-US小娇C | H1: 创奇-US黄怡D | I1: 创奇-US楷纯E | J1: 创奇-US淑谊F | K1: 创奇-US李珊G | L1: 创奇-US镱娜H | N1: MSKU | O1: 品名 | P1: 店铺-老
A2: JY01102 | B2: New1-【JY01102】-鲜花女孩婴儿沐浴蜂窝-进益 | C2: 进益-US | D2: =RIGHT(A2,1) -> 2 | N2: YS06736 | O2: 【YS06736】-黑金21岁雨帘2件套-艺胜 | P2: 艺胜-US
A3: JY01103 | B3: New1-【JY01103】-棒球1岁生日蜂窝九件套-进益（淘汰） | C3: 进益-US | D3: =RIGHT(A3,1) -> 3 | N3: CQ11873B | O3: 【CQ11873B】-粉香槟金18岁流苏花球套装-创奇（真空包装+外面套opp袋） | P3: 创奇-US
A4: JY01105 | B4: New1-【JY01105】-粉色1岁生日蜂窝八件套-进益（淘汰） | C4: 进益-US | D4: =RIGHT(A4,1) -> 5 | N4: CQ11874B | O4: 【CQ11874B】-粉香槟金21岁流苏花球套装-创奇（真空包装+外面套opp袋） | P4: 创奇-US
A5: JY01109 | B5: New1-【JY01109】-黑白30岁墓碑门联-进益（淘汰） | C5: 进益-US | D5: =RIGHT(A5,1) -> 9 | N5: CQ11861E | O5: 【CQ11861E】-玫瑰金50岁皇冠拉花小套装-创奇 | P5: 创奇-US
A6: JY01110 | B6: New1-【JY01110】-黑玫金气球40岁生日门联-进益（淘汰） | C6: 进益-US | D6: =RIGHT(A6,1) -> 0 | N6: CQ11865A | O6: 2026-【CQ11865A】-香槟金30岁照片横幅-创奇 | P6: 创奇-US
A7: JY01111 | B7: New1-【JY01111】-黑玫金气球无岁数生日门联-进益 | C7: 进益-US | D7: =RIGHT(A7,1) -> 1 | N7: CQ11892B | O7: 【CQ11892B】-黑金无岁数DIY惊喜红包弹跳盒-创奇 | P7: 创奇-US
A8: JY01113 | B8: New3-【JY01113】-黑玫金气球50岁生日门联-进益（淘汰） | C8: 进益-US | D8: =RIGHT(A8,1) -> 3 | N8: CQ11860F | O8: 2608-【CQ11860F】-ET-粉色女孩纪念拉旗套装-创奇（点胶固定+气球真空） | P8: 创奇-US
A9: JY01125 | B9: New5-【JY01125】-甜甜圈甜蜜1岁生日蜂窝-进益（淘汰） | C9: 进益-US | D9: =RIGHT(A9,1) -> 5 | N9: YS06737 | O9: 【YS06737】-黑金60岁雨帘2件套-艺胜 | P9: 艺胜-US
A10: JY01126 | B10: New6-【JY01126】-鲜花无岁数生日蜂窝-进益 | C10: 进益-US | D10: =RIGHT(A10,1) -> 6 | N10: DM21516 | O10: 2026-【DM21516】-香槟金18岁年份双横幅套装-大卖（点胶固定） | P10: 大卖-US
A11: JY01130 | B11: New7-【JY01130】-甜甜圈甜蜜2岁生日蜂窝-进益（淘汰） | C11: 进益-US | D11: =RIGHT(A11,1) -> 0 | N11: DM21518 | O11: 2026-【DM21518】-香槟金60岁年份双横幅套装-大卖（点胶固定） | P11: 大卖-US
A12: JY01132 | B12: New8-【JY01132】-鲜花无岁数生日漩涡-进益 | C12: 进益-US | D12: =RIGHT(A12,1) -> 2 | N12: CQ11891B | O12: 【CQ11891B】-黑金50岁图案纸扇套装-创奇（真空包装+外面套opp袋） | P12: 创奇-US
A13: JY01136 | B13: New9-【JY01136】-金粉80岁眼镜24件套-进益 | C13: 进益-US | D13: =RIGHT(A13,1) -> 6 | N13: CQ11895B | O13: 【CQ11895B】-玫瑰金40岁图案纸扇套装-创奇（真空包装+外面套opp袋） | P13: 创奇-US
... A71: SX00134 | B71: 【SX00134】-金粉无岁数生日长方形海报-势兴 | C71: 势兴-US | D71: =RIGHT(A71,1) -> 4 | N71: SX00475 | O71: 2609-【SX00475】-ET-彩色DIY岁数毛毡套装-势兴 | P71: 势兴-US
A72: SX00141 | B72: 【SX00141】-小号快乐露营长横幅-势兴（淘汰） | C72: 势兴-US | D72: =RIGHT(A72,1) -> 1
A73: SX00142 | B73: 【SX00142】-金粉16岁生日长方形海报-势兴 | C73: 势兴-US | D73: =RIGHT(A73,1) -> 2
A74: SX00143 | B74: 【SX00143】-玫瑰金内裤男人漩涡-势兴 | C74: 势兴-US | D74: =RIGHT(A74,1) -> 3
A75: SX00145 | B75: 【SX00145】-快乐露营桌面插件-势兴（淘汰） | C75: 势兴-US | D75: =RIGHT(A75,1) -> 5
A76: SX00146 | B76: 【SX00146】-多彩甜甜圈成长蛋糕签-势兴（淘汰） | C76: 势兴-US | D76: =RIGHT(A76,1) -> 6
A77: SX00153 | B77: 【SX00153】-金粉13岁生日门联-势兴 | C77: 势兴-US | D77: =RIGHT(A77,1) -> 3
A78: SX00156 | B78: 【SX00156】-金粉无岁数生日门联-势兴 | C78: 势兴-US | D78: =RIGHT(A78,1) -> 6
A79: SX00157 | B79: 【SX00157】-金粉25岁生日长方形海报-势兴 | C79: 势兴-US | D79: =RIGHT(A79,1) -> 7
A80: SX00159 | B80: 【SX00159】-金粉65岁生日长方形海报-势兴 | C80: 势兴-US | D80: =RIGHT(A80,1) -> 9
A81: SX00160 | B81: 【SX00160】-金粉75岁生日长方形海报-势兴 | C81: 势兴-US | D81: =RIGHT(A81,1) -> 0
A82: SX00161 | B82: 【SX00161】-金粉甜蜜16长横幅-势兴 | C82: 势兴-US | D82: =RIGHT(A82,1) -> 1
A83: SX00162 | B83: 【SX00162】-金粉21岁生日门联-势兴 | C83: 势兴-US | D83: =RIGHT(A83,1) -> 2
... A1983: SX00475 | B1983: 2609-【SX00475】-ET-彩色DIY岁数毛毡套装-势兴 | C1983: 势兴-US | D1983: =RIGHT(A1983,1) -> 5

Sheet 历史复原数据-计划自己判断复原
A2: JY01269 | B2: 已核对完 | I2: DM21464 | N2: CQ11747
A3: DM21464 | B3: 已核对完 | I3: SYC630 | N3: SYC598
A4: SX00432 | B4: 已核对完 | I4: SYC631 | N4: SYC599
A5: SX00433 | B5: 已核对完 | I5: SYC632 | N5: SYC600
A6: JY01306 | B6: 已核对完 | I6: SYC633 | N6: SYC601
A7: SX00440 | B7: 已核对完 | I7: CR32538 | N7: SYC602
A8: SYC594 | B8: 已核对完 | I8: CR32537 | N8: CQ11776
A9: SYC603 | B9: 已核对完 | I9: CR32500 | N9: CQ11777
A10: JY01313 | B10: 已核对完 | I10: CR32493 | N10: CQ11781
A11: JY01317 | B11: 已核对完 | I11: CR32492 | N11: CQ11787
A12: JY01318 | B12: 已核对完 | N12: CR32505
A13: CQ11752 | B13: 已核对完
A14: CQ11753 | B14: 已核对完
A15: CQ11754 | B15: 已核对完
A16: CQ11768 | B16: 已核对完
A17: CQ11769
A18: CQ11770
A19: CQ11771
A20: CQ11773
A21: CQ11779
A22: CQ11780
A23: CQ11782
A24: CQ11783
A25: CQ11784
A26: DX06015
A27: DX06016
A28: DX06017
... A46: JY01323
